<mujoco model="pendulum">
  <option timestep="0.05" iterations="1" ls_iterations="4" gravity="0 0 -10.0">
    <flag eulerdamp="disable"/>
  </option>
	<worldbody>
        <light diffuse=".5 .5 .5" pos="0 0 3" dir="0 0 -1"/>
		<body pos="0 0 2" euler="0 180 0">
			<joint name="pin" type="hinge" axis="0 -1 0" pos="0 0 0.5"/>
			<geom name="rod" type="cylinder" size="0.05 0.5" rgba="0 .9 0 1" mass="1.0"/>
		</body>
	</worldbody>
	<actuator>
		<motor joint="pin" name="torque_servo" ctrllimited="true" ctrlrange="-2 2" />
	</actuator>
</mujoco>